<?xml version="1.0" ?>
<!-- =================================================================================== -->
<!-- |    This document was autogenerated by xacro from /home/yappel/ros2_ws/src/smart_car/urdf/smartcar.urdf.xacro | -->
<!-- |    EDITING THIS FILE BY HAND IS NOT RECOMMENDED                                 | -->
<!-- =================================================================================== -->
<robot name="mobile_robot">
  <!-- Base link -->
  <link name="base_footprint"/>
  <joint name="chassis_joint" type="fixed">
    <parent link="base_footprint"/>
    <child link="Chassis_link"/>
    <origin rpy="0 0 0" xyz="0 0 0.032"/>
  </joint>
  <link name="Chassis_link">
    <visual>
      <geometry>
        <box size="0.257 0.17 0.05"/>
      </geometry>
      <material name="grey">
        <color rgba="0.5 0.5 0.5 1.0"/>
      </material>
    </visual>
    <collision>
      <geometry>
        <box size="0.257 0.17 0.05"/>
      </geometry>
    </collision>
    <inertial>
      <mass value="5.0"/>
      <inertia ixx="0.013083333333333334" ixy="0.0" ixz="0.0" iyy="0.02856208333333333" iyz="0.0" izz="0.03956208333333333"/>
    </inertial>
  </link>
  <joint name="base_link_joint" type="fixed">
    <parent link="Chassis_link"/>
    <child link="base_link"/>
    <origin rpy="0 0 0" xyz="0 0 0"/>
  </joint>
  <link name="base_link"/>
  <link name="back_left_wheel_link">
    <visual>
      <origin rpy="1.5707963267948966 0 0" xyz="0 0 0"/>
      <geometry>
        <cylinder length="0.025" radius="0.032"/>
      </geometry>
      <material name="black">
        <color rgba="0.1 0.1 0.1 1.0"/>
      </material>
    </visual>
    <collision>
      <origin rpy="1.5707963267948966 0 0" xyz="0 0 0"/>
      <geometry>
        <cylinder length="0.025" radius="0.032"/>
      </geometry>
    </collision>
    <inertial>
      <mass value="0.1"/>
      <inertia ixx="3.0808333333333335e-05" ixy="0.0" ixz="0.0" iyy="5.1200000000000004e-05" iyz="0.0" izz="3.0808333333333335e-05"/>
    </inertial>
  </link>
  <link name="back_right_wheel_link">
    <visual>
      <origin rpy="1.5707963267948966 0 0" xyz="0 0 0"/>
      <geometry>
        <cylinder length="0.025" radius="0.032"/>
      </geometry>
      <material name="black">
        <color rgba="0.1 0.1 0.1 1.0"/>
      </material>
    </visual>
    <collision>
      <origin rpy="1.5707963267948966 0 0" xyz="0 0 0"/>
      <geometry>
        <cylinder length="0.025" radius="0.032"/>
      </geometry>
    </collision>
    <inertial>
      <mass value="0.1"/>
      <inertia ixx="3.0808333333333335e-05" ixy="0.0" ixz="0.0" iyy="5.1200000000000004e-05" iyz="0.0" izz="3.0808333333333335e-05"/>
    </inertial>
  </link>
  <joint name="back_left_wheel_joint" type="continuous">
    <parent link="Chassis_link"/>
    <child link="back_left_wheel_link"/>
    <origin rpy="0 0 0" xyz="-0.1285 0.085 0"/>
    <axis xyz="0 1 0"/>
  </joint>
  <joint name="back_right_wheel_joint" type="continuous">
    <parent link="Chassis_link"/>
    <child link="back_right_wheel_link"/>
    <origin rpy="0 0 0" xyz="-0.1285 -0.085 0"/>
    <axis xyz="0 1 0"/>
  </joint>
  <link name="front_left_wheel_link">
    <visual>
      <origin rpy="1.5707963267948966 0 0" xyz="0 0 0"/>
      <geometry>
        <cylinder length="0.025" radius="0.032"/>
      </geometry>
      <material name="black">
        <color rgba="0.1 0.1 0.1 1.0"/>
      </material>
    </visual>
    <collision>
      <origin rpy="1.5707963267948966 0 0" xyz="0 0 0"/>
      <geometry>
        <cylinder length="0.025" radius="0.032"/>
      </geometry>
    </collision>
    <inertial>
      <mass value="0.1"/>
      <inertia ixx="3.0808333333333335e-05" ixy="0.0" ixz="0.0" iyy="5.1200000000000004e-05" iyz="0.0" izz="3.0808333333333335e-05"/>
    </inertial>
  </link>
  <link name="front_right_wheel_link">
    <visual>
      <origin rpy="1.5707963267948966 0 0" xyz="0 0 0"/>
      <geometry>
        <cylinder length="0.025" radius="0.032"/>
      </geometry>
      <material name="black">
        <color rgba="0.1 0.1 0.1 1.0"/>
      </material>
    </visual>
    <collision>
      <origin rpy="1.5707963267948966 0 0" xyz="0 0 0"/>
      <geometry>
        <cylinder length="0.025" radius="0.032"/>
      </geometry>
    </collision>
    <inertial>
      <mass value="0.1"/>
      <inertia ixx="3.0808333333333335e-05" ixy="0.0" ixz="0.0" iyy="5.1200000000000004e-05" iyz="0.0" izz="3.0808333333333335e-05"/>
    </inertial>
  </link>
  <joint name="front_right_wheel_steer_joint" type="revolute">
    <parent link="Chassis_link"/>
    <child link="front_right_steer_link"/>
    <origin xyz="0.1285 -0.085 0"/>
    <axis xyz="0 0 1"/>
    <limit effort="10" lower="-0.6" upper="0.6" velocity="100"/>
  </joint>
  <link name="front_right_steer_link">
    <inertial>
      <mass value="0.05"/>
      <inertia ixx="8.333333333333333e-07" ixy="0.0" ixz="0.0" iyy="8.333333333333333e-07" iyz="0.0" izz="8.333333333333333e-07"/>
    </inertial>
  </link>
  <joint name="front_right_wheel_joint" type="continuous">
    <parent link="front_right_steer_link"/>
    <child link="front_right_wheel_link"/>
    <origin xyz="0 0 0"/>
    <axis xyz="0 1 0"/>
  </joint>
  <joint name="front_left_wheel_steer_joint" type="revolute">
    <parent link="Chassis_link"/>
    <child link="front_left_steer_link"/>
    <origin xyz="0.1285 0.085 0"/>
    <axis xyz="0 0 1"/>
    <limit effort="10" lower="-0.6" upper="0.6" velocity="100"/>
  </joint>
  <link name="front_left_steer_link">
    <inertial>
      <mass value="0.05"/>
      <inertia ixx="8.333333333333333e-07" ixy="0.0" ixz="0.0" iyy="8.333333333333333e-07" iyz="0.0" izz="8.333333333333333e-07"/>
    </inertial>
  </link>
  <joint name="front_left_wheel_joint" type="continuous">
    <parent link="front_left_steer_link"/>
    <child link="front_left_wheel_link"/>
    <origin xyz="0 0 0"/>
    <axis xyz="0 1 0"/>
  </joint>
  <!-- ==================== IMU SENSOR ==================== -->
  <!-- Add IMU link & mount BEFORE sensor definition -->
  <link name="imu_link">
    <inertial>
      <mass value="0.01"/>
      <inertia ixx="1e-6" ixy="0" ixz="0" iyy="1e-6" iyz="0" izz="1e-6"/>
    </inertial>
  </link>
  <joint name="imu_mount" type="fixed">
    <parent link="base_link"/>
    <child link="imu_link"/>
    <origin rpy="0 0 0" xyz="0 0 0.08"/>
  </joint>
  <gazebo reference="imu_link">
    <sensor name="imu_sensor" type="imu">
      <always_on>true</always_on>
      <update_rate>100.0</update_rate>
      <imu>
        <noise>
          <!-- noise parameters kept -->
        </noise>
      </imu>
      <plugin filename="libgazebo_ros_imu_sensor.so" name="imu_plugin">
        <ros>
          <namespace>/</namespace>
          <remapping>/imu_plugin/out:=/imu_data</remapping>
        </ros>
      </plugin>
    </sensor>
  </gazebo>
  <!-- ==================== LIDAR SENSOR ==================== -->
  <link name="sllidar_base_link">
    <visual>
      <geometry>
        <cylinder length="0.05" radius="0.04"/>
      </geometry>
      <material name="red">
        <color rgba="1 0 0 1"/>
      </material>
    </visual>
  </link>
  <joint name="lidar_joint" type="fixed">
    <parent link="base_link"/>
    <child link="sllidar_base_link"/>
    <origin rpy="0 0 0" xyz="0.1285 0 0.1"/>
  </joint>
  <gazebo reference="sllidar_base_link">
    <sensor name="lidar_sensor" type="ray">
      <pose>0 0 0 0 0 0</pose>
      <visualize>true</visualize>
      <update_rate>20.0</update_rate>
      <ray>
        <scan>
          <horizontal>
            <samples>200</samples>
            <resolution>1</resolution>
            <min_angle>-0.7854</min_angle>
            <max_angle>0.7854</max_angle>
          </horizontal>
        </scan>
        <range>
          <min>0.12</min>
          <max>6.0</max>
          <resolution>0.01</resolution>
        </range>
        <noise>
          <type>gaussian</type>
          <mean>0.0</mean>
          <stddev>0.01</stddev>
        </noise>
      </ray>
      <plugin filename="libgazebo_ros_ray_sensor.so" name="gazebo_ros_laser">
        <ros>
          <namespace>/</namespace>
          <remapping>/gazebo_ros_laser/out:=/scan</remapping>
        </ros>
        <output_type>sensor_msgs/LaserScan</output_type>
        <frame_name>sllidar_base_link</frame_name>
      </plugin>
    </sensor>
  </gazebo>
  <!-- VEHICLE CONTROL PLUGIN OUTSIDE SENSOR -->
  <gazebo>
    <plugin filename="libcar_gazebo_plugin.so" name="car_gazebo_plugin">
      
    </plugin>
  </gazebo>
</robot>
